Workbook
Name Interes: #REF!
Name Capital: #REF!
Name Capital: #REF!
Name Interes: #REF!

Sheet PORTADA Y RESUMEN EJECUTIVO
F15: PLAN DE NEGOCIO DE
F16: TRIBU
H26: PONFERRADA, | I26: 46234
A36: SUMARIO
D37: RESUMEN EJECUTIVO | H37: (D): Participante con soporte del Director
D38: Descripción de la Idea de Negocio (D) | H38: (I): Participante con soporte del Consultor de Innovación
D39: Experiencia de los Promotores (D) | H39: (M): Participante con soporte del Consultor de Marketing
D40: Síntesis INCYNCO | H40: (EM): Consultor Experto en la Materia
A42: Introducción de datos en celdas grises | F42: ¿POR QUÉ?
F43: Observaciones del Mercado que suscitan la Idea (D)
F44: Macroentorno: análisis PEST (D)
F45: Microentorno: Análisis de PORTER (D)
D46: ¿PARA QUIÉN? | F46: Competencia (D)
D47: (D) Hábitos de consumo y posibles tendencias | F47: Análisis DAFO y estrategias CAME (D)
D48: (D) Segmentos de Clientes: cuantificación | F48: Resumen POR QUÉ (D)
D49: (D) Mapas de Empatía
D50: (D) Segmentos alternativos de Clientes | H50: ¿EL QUÉ?
D51: (D) Cálculo del Mercado potencial | H51: Productos/Servicios que materializan la Idea (M)
D52: (D) Resumen PARA QUIÉN | H52: Matriz Productos-Segmentos de Clientes (M)
H53: Alianzas Estratégicas (M)
E54: ¿CÓMO? | H54: Resumen EL QUÉ (D)
E55: (I) Canvas
E56: (EM) Plan de Marketing y Comercialización | G56: ¿CUÁNTO Y CUÁNDO?
E57: (EM) Plan de Operaciones | G57: Plan Financiero (EM)
E58: (EM) Plan de Infraestructura Informática y Marketing Digital | G58: Análisis de las Inversiones y su financiación (EM)
E59: (EM) Plan Jurídico, Fiscal y de RR.HH | G59: Ratios
E60: (EM) Plan de Innovación y Sostenibilidad | G60: Cronograma de implantación (D)
E61: (D) Resumen CÓMO | G61: Resumen CUÁNTO-CUÁNDO (D)
A63: RESUMEN EJECUTIVO
F66: Descripción de la Idea de Negocio
A68: Estudio de diseño web y presencia digital para pymes, autónomos y bodegas de Ponferrada y El Bierzo, constituido como Sociedad Limitada por dos socios promotores con papeles complementarios: producción y dirección técnica (Socia 1) y dirección comercial (Socio 2). No vende "páginas web": vende presencia digital que capta clientes y se mantiene viva. Cinco líneas: diseño y desarrollo de sitios web, identidad visual y diseño gráfico, mantenimiento gestionado por cuota mensual y SEO local (Google Business Profile). Las dos líneas recurrentes suponen el 27,5% de la facturación del Año 1 y son crecientes: es lo que diferencia el negocio de un freelance por proyectos y lo que sostiene la caja los meses sin cierre de venta.
A99: RESUMEN EJECUTIVO
E102: Socios Promotores
A104: Socio 1 | B104: María Gabriela Pérez Sánchez | F104: Socio 2 | G104: Wilmer José Pérez Yanéz
A105: Experiencia | B105: Disenadora web con experiencia en diseño y producción de sitios web para pymes en BeeDigital (proveedor nacional de presencia digital para pequeños negocios). Conocimiento directo del ciclo completo: captación, briefing, producción, entrega y mantenimiento. Residente en Ponferrada, con red de contactos en el tejido empresarial del Bierzo. | F105: Experiencia | G105: Profesional con amplia experiencia en gestión comercial, liderazgo de equipos y competencias para crear, organizar y poner en marcha planes comerciales. Asume la DIRECCIÓN COMERCIAL de la sociedad con dedicación retribuida desde el Año 1 (12.000 EUR líquidos anuales): prospección, visita a cliente, cierre y desarrollo de la red de prescriptores (gestorías, imprentas y agencias de la comarca). Su incorporación como socio resuelve la debilidad estructural del plan original, donde una sola persona tenía que producir y vender a la vez y la venta siempre perdía. Es también la razón de que la forma jurídica sea Sociedad Limitada y no empresaria individual: esta última no admite socios.
A116: Socio 3 | F116: Socio 4
A117: Experiencia | F117: Experiencia
F128: Datos de contacto
A130: Teléfonos | B130: 643958978 | F130: e-mails | G130: mariaperezart@gmail.com
A133: RESUMEN EJECUTIVO
...

Sheet POR QUÉ
A1: ¿POR QUÉ?
F4: Observaciones del Mercado que suscitan la Idea
A5: La oportunidad de 2026 ya no es la ausencia de web, es la mala web. El dato que justificaba este proyecto en 2023 ("el 78% de autónomos y pymes no tiene página web", encuesta GoDaddy a 400 negocios) está obsoleto: en 2026 alrededor del 76% de las pymes españolas ya tiene web y solo un 24% carece de ella. El Kit Digital (2022-2025) financió decenas de miles de sitios web, y la solución "Sitio web y presencia en internet" fue la más demandada del programa (32% de los bonos). El resultado en El Bierzo es un parque de sitios web construidos deprisa, con plantilla, sin mantenimiento posterior y sin posicionamiento local. De ahí surge la idea: el mercado ya no paga por "tener una web", paga por que la web funcione, este actualizada, sea segura y traiga clientes. Tres hechos lo sostienen. (1) Muchos sitios financiados por Kit Digital han cumplido ya su periodo de mantenimiento obligatorio y quedan huerfanos de proveedor. (2) La factura electrónica B2B obligatoria (Ley 18/2022 Crea y Crece, y el sistema Verifactu) obliga a miles de micronegocios a tocar sus sistemas digitales. (3) Los constructores web con IA han hundido el precio de "una web bonita", lo que expulsa del mercado a quien solo vende maquetación y premia a quien vende criterio, contenido local y continuidad. FUENTES: ONTSI/Ministerio, Informe de digitalización de las pymes; DESI 2024 (España, puesto 14 de 27); datos de ejecución del programa Kit Digital, acelerapyme.gob.es.
A37: ¿POR QUÉ?
F40: Macroentorno: análisis PEST
B42: Factores Político-Legales | C42: LSSI-CE (Ley 34/2002): avisos legales, cookies y comunicaciones comerciales. RGPD (UE) 2016/679 y LOPDGDD (LO 3/2018): base jurídica, contratos de encargado de tratamiento con cada cliente, registro de actividades. Ley 18/2022 "Crea y Crece" + Verifactu (RD 1007/2023): factura electrónica B2B y software de facturación certificado. Genera demanda de servicio y obliga también al propio negocio. Reglamento Europeo de IA (2024): obligaciones de transparencia si se usan modelos generativos en entregables de cliente. Kit Digital: cerrado a nuevas solicitudes desde octubre de 2025; siguen vivos bonos concedidos pendientes de ejecutar (Orden TDF/39/2026 amplia plazos). Ser Agente Digitalizador adherido sigue siendo una vía de entrada.
B49: Factores Económicos | C49: Inflación prevista en España del 3,6% en 2026 y 2,6% en 2027 (Banco de España, junio 2026): presiona costes de licencias y salarios, no tanto los precios de venta. Cotización de autónomos por ingresos reales: 15 tramos congelados en 2026, de 200 a 601,57 EUR/mes, con regularización anual. Tarifa plana de 80 EUR/mes los 12 primeros meses. El Bierzo en transición justa post-carbon: fondos de reindustrialización y un tejido de micronegocios que se renueva. Ponferrada crece en población por tercer año consecutivo (63.444 habitantes a 1/1/2026, ~64.000 en abril), tras 12 años de caida. Mercado local pequeño pero estabilizado. Riesgo real: baja disposición a pagar del micronegocio local y competencia de precio de plataformas con IA.
B56: Factores Socioculturales | C56: El cliente pequeño ya no pregunta "necesito una web?", pregunta "por qué la mía no aparece en Google?". El eje de conversación se ha desplazado de existir a competir. WhatsApp e Instagram son el canal real de atención del micronegocio berciano; la web actua como prueba de solvencia, no como único escaparate. Preferencia marcada por el proveedor cercano y con cara visible: en un mercado de 63.000 habitantes la recomendación boca a boca pesa más que cualquier campaña. Enoturismo y Camino de Santiago traen demanda estacional de presencia digital en inglés para bodegas, alojamientos y hostelería.
B63: Factores Tecnológicos | C63: IA generativa: reduce el tiempo de producción de textos, imágenes y maquetación. Oportunidad como herramienta interna (más margen por proyecto) y amenaza como sustitutivo (Wix ADI, Framer, Lovable, v0, Canva Websites permiten a un profano publicar una web en horas). Consecuencia estratégica: el valor deja de estar en maquetar y pasa a estar en diagnóstico, contenido con conocimiento local, integración (reservas, pagos, facturación) y continuidad. WordPress sigue siendo el estandar del segmento; el ecosistema de mantenimiento y seguridad es una fuente de ingreso recurrente estable. Nuevo vector 2026: optimización para respuestas de IA (que la ficha del negocio sea citable por asistentes conversacionales), aún sin proveedor local que lo ofrezca.
A72: ¿POR QUÉ?
F75: Microentorno: Análisis de PORTER
F78: Posibles nuevos competidores
D79: MUY ALTA. Barreras de entrada casi nulas y, desde 2024-2025, los constructores web con IA permiten que el propio cliente o un aficionado publique un sitio en horas. La defensa no es técnica: es marca local, cartera de mantenimiento y conocimiento del sector del cliente.
A85: Dependencia de Proveedores | B85: Proveedores fácilmente sustituibles: BAJA dependencia | I85: Cliente muy sensible al precio en el proyecto inicial | K85: ALTA en proyecto puntual, BAJA en cuota de mantenimiento: una vez el sitio está bajo contrato, el coste de cambiar de proveedor supera el ahorro. Es el argumento central para empujar la venta hacia lo recurrente.
F86: Situación actual
E87: Sector muy competitivo y fragmentado. En El Bierzo conviven cuatro perfiles: freelance local a precio bajo, agencia de marketing de Ponferrada o León con servicio completo, proveedores nacionales de bajo coste con cuota mensual (BeeDigital, Webempresa, Wix) y, desde 2024, plataformas de IA que compiten a coste prácticamente cero. Ninguno domina el nicho de "mantenimiento continuado + SEO local con proveedor presencial".
F94: de la competencia en el Mercado
D97: Plataformas SaaS de autoservicio y constructores con IA (Wix, Squarespace, Shopify, Framer, Canva Websites). Cubren el 80% de la necesidad al 10% del precio para el cliente que solo quiere existir. No cubren integración, contenido local, ni responsabilidad sobre el resultado.
F102: Posibles productos sustitutivos
A106: ¿POR QUÉ?
F109: Análisis de la Competencia
B111: EMPRESA | D111: PRODUCTOS QUE COMERCIALIZA | G111: PRECIOS | I111: CARACTERÍSTICAS
B112: Agencias de marketing de Ponferrada y León | D112: Web, campañas, RRSS, branding, medios | G112: 1.500-6.000 EUR proyecto; 300-800 EUR/mes | I112: Servicio completo y trato presencial. Foco en captación, no en operación. Poco interes en el ticket pequeño de mantenimiento.
B115: Freelance local / diseñador por cuenta propia | D115: Web WordPress, logotipos, piezas gráficas | G115: 400-1.200 EUR proyecto | I115: Competidor directo en precio. Sin estructura, sin garantía de continuidad ni soporte. Es de donde llegan los sitios abandonados que hoy son la oportunidad.
B118: Proveedores nacionales de presencia digital (BeeDigital y similares) | D118: Web + ficha en directorios + SEO básico, por cuota | G118: 50-150 EUR/mes con permanencia | I118: Escala y precio bajo. Servicio estandarizado, sin interlocutor fijo ni conocimiento del cliente. Alta rotación por insatisfacción: fuente natural de clientes.
B121: Plataformas SaaS de autoservicio (Wix, Squarespace, Shopify) | D121: Constructor web, hosting y plantillas | G121: 15-60 EUR/mes | I121: Amenaza estructural en la gama baja. Traslada todo el trabajo y el riesgo al cliente. No hay diagnóstico ni responsabilidad sobre el resultado.
B124: Constructores web con IA (Framer AI, Lovable, v0, Canva) | D124: Generación de sitio completo a partir de texto | G124: 0-30 EUR/mes | I124: Hunden el precio de la maquetación pura. No resuelven SEO local, integraciones, contenido veraz del negocio ni mantenimiento. Se usan como herramienta interna, no se combaten de frente.
B127: Consultoras TIC y partners de Kit Digital | D127: Digitalización subvencionada, ERP/CRM, web | G127: Según bono (2.000-29.000 EUR) | I127: Muy activos hasta el cierre de solicitudes (oct-2025). Dejan cartera instalada sin servicio postventa: el mercado de sustitución.
B130: Imprentas y rotulación del Bierzo con servicio de diseño | D130: Diseño gráfico, papelería, cartelería | G130: 150-800 EUR proyecto | I130: Competencia solo en la línea de diseño gráfico. Posible aliado prescriptor más que rival: derivan el trabajo web que no saben hacer.
A141: ¿POR QUÉ?
F144: Análisis DAFO
B146: Factores Internos (Presentes) | G146: Factores Externos (Futuros)
B148: DEBILIDADES | G148: AMENAZAS
B149: Cartera de clientes inexistente al inicio y sin marca conocida en el Bierzo. Capacidad de producción concentrada en una sola persona: el Socio 2 vende pero no produce, así que un pico de trabajo o una baja de la Socia 1 frena la entrega. Sin historial de proyectos propios que enseñar (portfolio de terceros). Estructura de sociedad más cara que la de autónomo: contabilidad mercantil, cuentas anuales y dos cuotas de RETA societario. El Año 1 se planifica en equilibrio: cubre los sueldos de los dos socios pero no genera beneficio ni colchón más allá del capital aportado. Sin experiencia previa conjunta: los dos socios no han trabajado juntos en este negocio y el reparto de decisiones está sin rodar. | G149: Constructores web con IA: hunden el precio de la maquetación (amenaza principal). Barreras de entrada prácticamente nulas: cualquiera puede competir mañana. Baja disposición a pagar del micronegocio del Bierzo. Fin del Kit Digital como generador de demanda subvencionada (cerrado a solicitudes desde octubre de 2025). Mercado local pequeño: 63.444 habitantes en Ponferrada; riesgo de agotar el nicho. Impago o retraso en el cobro del cliente micropyme. Inflación del 3,6% en 2026 encareciendo licencias y salarios.
B160: FORTALEZAS | G160: OPORTUNIDADES
B161: DOS PERFILES COMPLEMENTARIOS Y NO SOLAPADOS: producción y dirección técnica (Socia 1) y dirección comercial (Socio 2). En un sector donde el freelance típico produce bien y vende mal, tener a alguien dedicado a vender desde el mes uno es la ventaja competitiva más difícil de copiar. Conocimiento del mercado local y residencia en Ponferrada: proveedor con cara visible frente a plataformas remotas. Experiencia real de producción web en BeeDigital: se conoce por dentro al competidor nacional de cuota y sus puntos débiles. Dominio de las dos disciplinas (web y gráfico): permite vender identidad completa, no solo el sitio. Uso intensivo de IA en producción: más margen por proyecto que el freelance clásico. Responsabilidad limitada: el patrimonio personal de los socios no responde de las deudas sociales, algo relevante al manejar webs y datos de terceros. | G161: Parque instalado de webs de Kit Digital sin mantenimiento ni proveedor: mercado de sustitución identificado y cuantificable. Factura electrónica B2B obligatoria (Crea y Crece / Verifactu): obliga a miles de micronegocios a revisar sus sistemas. DO Bierzo (aprox. 70 bodegas) y enoturismo: necesidad de web en varios idiomas y venta online, con ticket superior a la media local. Camino de Santiago: alojamientos y hostelería con demanda de reserva directa. Subvenciones vigentes: Ayuntamiento de Ponferrada (consolidación del trabajo autónomo, convocatoria 2026) y CONSOLIDACYL de la Junta de Castilla y León. Ponferrada gana población por tercer año consecutivo. Nadie en la comarca ofrece aún optimización para asistentes de IA.
A176: ¿POR QUÉ?
F179: CAME: Determinación de Estrategias
B181: Corregir Debilidades | G181: Afrontar Amenazas
B183: Estrategias de Reorientación | G183: Estrategias de Supervivencia
...

Sheet PARA QUIÉN
A1: ¿PARA QUIÉN?
F4: Hábitos de consumo y posibles tendencias
A6: El habito de consumo ha cambiado de naturaleza. Entre 2020 y 2023 el micronegocio compraba presencia: "necesito estar en internet". En 2026 ya está, y lo que compra es rendimiento: aparecer en la busqueda local, que el formulario funcione, que la ficha de Google este viva, que se pueda reservar o pagar sin llamar. La economía digital ya supone en torno al 27% del PIB español y el 76% de las pymes tiene web: el problema dejó de ser la ausencia y pasó a ser la calidad y el abandono. Tres tendencias marcan la decisión de compra del cliente del Bierzo en 2026: 1. Del proyecto a la suscripción. El micronegocio prefiere una cuota mensual previsible a un desembolso de 1.500 EUR. Es la forma en que ya compra el software, el móvil y la gestoría. Un plan de negocio que solo venda proyectos ignora como compra realmente su cliente. 2. Del escaparate a la conversación. La primera interacción ocurre en WhatsApp, Instagram o la ficha de Google Business, no en la home. La web se ha convertido en el lugar donde se confirma la confianza y se cierra la transacción. 3. De buscar a preguntar. Una parte creciente de las consultas se resuelve en asistentes de IA que citan fuentes. Aparecer ahí depende de datos estructurados y coherencia entre web, ficha de Google y directorios: un servicio que hoy no ofrece nadie en la comarca. Consecuencia: el cliente ya no compara "cuanto cuesta una web" sino "quien se ocupa de que esto funcione todos los meses". Eso favorece al proveedor local con contrato de continuidad y penaliza tanto al freelance de proyecto puntual como a la plataforma remota sin interlocutor.
A37: ¿PARA QUIÉN?
C40: Segmentos de Clientes: Identificación y Cuantificación
B42: Descripción | G42: Estimación Numérica | J42: Fuentes
A44: Segmento 1 | B44: Pymes y micropymes de Ponferrada y El Bierzo (comercio, servicios, construcción, industria auxiliar). Núcleo del negocio: necesitan web operativa, identidad coherente y mantenimiento continuado. | G44: 6400 | I44: Directorios de empresas de Ponferrada (Iberinform / einforma), 2026. Cifra de empresas con domicilio en el municipio; VERIFICAR contra DIRCE-INE antes de presentar el plan.
A49: Segmento 2 | B49: Autónomos y profesionales del Bierzo (asesorías, clínicas, abogados, reformas, hostelería, formación). Ticket menor, ciclo de venta corto, alta sensibilidad al precio inicial: entran mejor por cuota que por proyecto. | G49: 9300 | I49: Estimación propia: 34.349 autónomos afiliados al RETA en la provincia de León (Seguridad Social, abril 2026) x 27% de peso poblacional de la comarca del Bierzo. ES UNA ESTIMACIÓN, no un dato oficial comarcal.
A54: Segmento 3 | B54: Bodegas de la DO Bierzo y enoturismo. Segmento de mayor valor: web multiidioma, venta online, reservas de visita. Ticket medio muy superior y fuerte efecto demostración dentro del sector. | G54: 70 | I54: Consejo Regulador DO Bierzo (bodegas inscritas, orden de magnitud). CONFIRMAR cifra vigente en crdobierzo.es.
A59: Segmento 4 | B59: Alojamiento y hostelería del Camino de Santiago (albergues, casas rurales, restaurantes). Demanda de reserva directa para reducir la comisión de los portales. Estacionalidad marcada: contratar en invierno para la temporada. | G59: 260 | I59: Estimación propia a partir del registro de alojamientos turisticos de la Junta de Castilla y León en la comarca del Bierzo. VERIFICAR.
A64: Segmento 5
A72: ¿PARA QUIÉN?
F75: Mapas de Empatía
B77: ¿Qué piensa el Cliente? | D77: ¿Cómo es su entorno? | F77: ¿Qué ve en el Mercado? | H77: ¿Qué dificultades tiene? | J77: ¿A qué aspira?
A79: Segmento 1 | B79: Que piensa: "mi web está anticuada y no me trae nada, pero cambiarla es un lio y no sé a quién creer". | D79: Entorno: 1 a 9 empleados, sin persona dedicada a marketing. La web la hizo alguien que ya no responde. | F79: Ve en el mercado: ofertas de 300 EUR y de 3.000 EUR sin entender la diferencia. Desconfianza generalizada. | H79: Dificultades: no sabe evaluar una propuesta técnica, teme pagar dos veces y no tiene tiempo para el proyecto. | J79: Aspira a: que le entre trabajo por internet sin tener que ocuparse de nada.
A84: Segmento 2 | B84: Que piensa: "invertir en esto me da miedo, no sé si lo voy a recuperar". | D84: Entorno: trabaja solo o con una persona. Factura entre 20.000 y 60.000 EUR. Decide en el dia. | F84: Ve en el mercado: Wix a 20 EUR/mes frente a presupuestos de 1.200 EUR. Ve precio, no diferencia de valor. | H84: Dificultades: presupuesto muy ajustado y cero tiempo. Ya lo intento solo y lo dejo a medias. | J84: Aspira a: parecer profesional y aparecer en Google cuando alguien busca su servicio en Ponferrada.
A89: Segmento 3 | B89: Que piensa: "vendo un producto premium y mi web no lo parece; además no la entiende un comprador extranjero". | D89: Entorno: bodega familiar o mediana, con distribución y algo de exportación. Estacionalidad de vendimia y enoturismo. | F89: Ve en el mercado: bodegas de Rioja y Ribera con webs muy superiores. Compara hacia arriba, no hacia abajo. | H89: Dificultades: necesita varios idiomas, venta online con logística de vino y reserva de visitas. Nadie local se lo resuelve entero. | J89: Aspira a: vender directo sin intermediario y llenar las visitas de enoturismo todo el año.
A94: Segmento 4 | B94: Que piensa: "Booking se lleva el 18% de cada reserva y no puedo hacer nada". | D94: Entorno: albergue, casa rural o restaurante en el Camino. Temporada fuerte de mayo a octubre. | F94: Ve en el mercado: dependencia total de portales y de las resenas. | H94: Dificultades: no tiene motor de reserva propio ni sabe integrarlo. Fuera de temporada no tiene ingresos para invertir. | J94: Aspira a: reserva directa y clientes que repitan sin pagar comisión.
A99: Segmento 5 | B99: Que piensa: "necesito quitarme de encima este encargo web sin perder al cliente". | D99: Entorno: agencia, imprenta o gestoría del Bierzo con cliente que pide algo fuera de su alcance. | F99: Ve en el mercado: freelances poco fiables que le dejan tirado ante su propio cliente. | H99: Dificultades: necesita cumplimiento de plazos y discreción. No puede arriesgar su relación comercial. | J99: Aspira a: un proveedor de confianza al que derivar sin supervisar.
K105: Inspirado en el Diagrama de Empatía desarrollado por XPLANE
A106: ¿PARA QUIÉN?
F109: Segmentos alternativos de Clientes
B111: Descripción | G111: Estimación Numérica | J111: Fuentes
A113: Segmento Alternativo 1 | B113: Agencias de marketing, imprentas, rotulación y gestorías del Bierzo y León como PRESCRIPTORES, no como clientes finales: subcontratan la producción web y gráfica que no cubren. Margen menor pero flujo estable y sin coste de captación. | G113: 60 | I113: Directorio de agencias y servicios de marketing de la provincia de León.
A118: Segmento Alternativo 2 | B118: Clientes en remoto fuera del Bierzo captados por recomendación o por posicionamiento orgánico. Sin coste de captación pero sin ventaja de proximidad: se acepta lo que llegue, no se persigue. | G118: 0 | I118: No cuantificado: canal oportunista, no planificado.
A123: Segmento Alternativo 3
A141: ¿PARA QUIÉN?
F144: Cálculo del Mercado Potencial
C146: Ámbito geográfico | F146: Clientes Potenciales | I146: Tipo de Cliente
B148: Segmento 1 | C148: Local | F148: De 1.000 a 10.000 | I148: De Proximidad
B150: Segmento 2 | C150: Local | F150: De 1.000 a 10.000 | I150: De Proximidad
B152: Segmento 3 | C152: Local | F152: Menos de 1.000 | I152: De Proximidad
B154: Segmento 4 | C154: Local | F154: Menos de 1.000 | I154: De Proximidad
B156: Segmento 5 | C156: Regional | F156: Menos de 1.000 | I156: Disperso
B158: Segmentos Alternativos
C160: Regional | F160: Menos de 1.000 | I160: Disperso
C161: Regional | F161: De 1.000 a 10.000 | I161: Transeunte
C162: Nacional | F162: De 10.000 a 100.000 | I162: Disperso
C163: Internacional | F163: Más de 100.000 | I163: Virtual
F164: Varios Millones
...

Sheet CÓMO
A1: ¿CÓMO? | K1: CANVAS
A4: Asociaciones clave | C4: Actividades clave | E4: Propuesta de Valor | H4: Relaciones con Clientes | J4: Segmentos de Mercado
A6: Proveedor de hosting gestionado Asesoría fiscal-laboral de Ponferrada Freelances de producción (picos) Imprenta y rotulación local Gestorías y agencias prescriptoras Cámara de Comercio y CONFEBIERZO | C6: Prospección y venta consultiva Diagnóstico digital del cliente Diseño y producción web Diseño gráfico e identidad Mantenimiento y seguridad SEO local y ficha de Google Formación continua | E6: Presencia digital que funciona todos los meses, con un proveedor local con cara visible: web + identidad + mantenimiento + SEO local en un solo interlocutor. | H6: Personalizada y continuada: interlocutor único, revisión trimestral presencial incluida en la cuota de mantenimiento. | J6: Pymes y micropymes del Bierzo Autónomos y profesionales Bodegas DO Bierzo y enoturismo Alojamiento del Camino Agencias y gestorías (prescriptores)
C17: Recursos Clave | H17: Canales
C19: Socia 1: producción y dirección técnica (dedicación completa) Socio 2: dirección comercial (dedicación retribuida) Red de freelances para picos de producción Equipo informático y software Dos puestos en coworking Portfolio y casos locales publicados Biblioteca propia de plantillas y procesos | H19: Directo: venta presencial y telefónica en Ponferrada y comarca. Prescriptores: gestorías, imprentas y agencias. Digital: web propia, SEO local y ficha de Google Business.
A29: Estructura de Costes | G29: Fuentes de Ingresos
A31: Retribución de los dos socios (72% de la estructura) RETA societario de ambos (tarifa plana 80 EUR/mes el Año 1) Licencias de software e IA Dos puestos de coworking y conectividad Asesoría de sociedad: contabilidad, IS y cuentas anuales Publicidad y marketing local Hosting y dominios Desplazamientos por la comarca Subcontratación variable de producción (va a coste de ventas) | G31: NO RECURRENTE (72,5% Año 1) Web esencial: 1.200 EUR Web profesional / e-commerce: 3.500 EUR Identidad visual y gráfico: 950 EUR RECURRENTE (27,5% Año 1, objetivo 35% en Año 3) Mantenimiento gestionado: 60 EUR/mes SEO local: 250 EUR/mes
A37: ¿CÓMO? | K37: Plan de Marketing y Comercialización
F40: Propuesta de Valor y su Comunicación
A42: PROPUESTA DE VALOR "Tu presencia digital, funcionando todos los meses, con alguien de Ponferrada al otro lado del teléfono." El posicionamiento no es el precio ni el diseño: es la CONTINUIDAD con proveedor cercano. En 2026 cualquiera puede generar una web bonita con IA en una tarde; casi nadie se hace responsable de que siga funcionando, posicionando y vendiendo dentro de un año. QUE SE COMUNICA, POR SEGMENTO - Pyme con web abandonada: "tu web no está rota, está sola. Nosotros nos ocupamos." - Autónomo sin presupuesto: "empieza por 60 EUR al mes y crece cuando te entre trabajo." - Bodega DO Bierzo: "vende tu vino directo, en tres idiomas, sin intermediario." - Alojamiento del Camino: "cada reserva directa es un 18% que no le pagas a un portal." - Prescriptor: "te resuelvo el encargo web sin tocar tu relación con el cliente." ARGUMENTO FRENTE A LAS TRES OBJECIONES REALES 1. "Me lo hago con IA por 20 EUR/mes" -> La herramienta es gratis; lo que se paga es saber que poner, que no aparezca en Google el nombre mal escrito, y que alguien lo arregle cuando falle un martes a las nueve. 2. "Ya me lo hizo uno del Kit Digital" -> Perfecto: audito gratis en 15 minutos que ha pasado con el desde entonces. 3. "Es caro" -> Comparar contra el coste de un mes sin teléfono sonando, no contra el precio de una plantilla. CANALES DE COMUNICACIÓN Prospección directa presencial (dos mañanas fijas por semana, no negociables), prescriptores, ficha de Google Business optimizada, contenido local en la web propia ("diseño web Ponferrada", "tienda online bodega Bierzo"), LinkedIn e Instagram con formato antes/después de proyectos reales, y presencia en Cámara de Comercio, CONFEBIERZO y el Centro de Innovación y Emprendimiento de Ponferrada.
A73: ¿CÓMO? | K73: Plan de Marketing y Comercialización
C76: Precio de Venta | E76: Coste | G76: Margen Absoluto | I76: Margen s/Venta
A78: ='EL QUÉ'!A8 | C78: 1200 | E78: 150 | G78: =C78-E78 | I78: =IF(C78="","",G78/C78)
A83: =IF('EL QUÉ'!A13="","",'EL QUÉ'!A13) | C83: 3500 | E83: 600 | G83: =C83-E83 | I83: =IF(C83="","",G83/C83)
A88: =IF('EL QUÉ'!A18="","",'EL QUÉ'!A18) | C88: 950 | E88: 60 | G88: =C88-E88 | I88: =IF(C88="","",G88/C88)
A93: =IF('EL QUÉ'!A23="","",'EL QUÉ'!A23) | C93: 720 | E93: 180 | G93: =C93-E93 | I93: =IF(C93="","",G93/C93)
C98: 3000 | E98: 480 | G98: =C98-E98 | I98: =IF(C98="","",G98/C98)
A109: ¿CÓMO? | K109: Plan de Marketing y Comercialización
F112: Canales de Comercialización
E114: Canal | I114: Situación Actual
A116: ='EL QUÉ'!A8 | C116: Directo | I116: Planificado
A121: =IF('EL QUÉ'!A13="","",'EL QUÉ'!A13) | C121: Directo | I121: Planificado
A126: =IF('EL QUÉ'!A18="","",'EL QUÉ'!A18) | C126: Directo | I126: Planificado
A131: =IF('EL QUÉ'!A23="","",'EL QUÉ'!A23) | C131: Directo | I131: Planificado
A136: =IF('EL QUÉ'!A28="","",'EL QUÉ'!A28) | C136: Directo | I136: Planificado
C140: Directo | E140: Planificado
C141: Indirecto | E141: Negociado
C142: Virtual | E142: Contratado
A147: ¿CÓMO? | K147: Plan de Marketing y Comercialización
F149: Comunicación con el Mercado
D151: Acciones | G151: Gastos al Inicio | I151: Gastos Año 1
A153: ='EL QUÉ'!A8 | C153: Prospección directa, ficha de Google Business, SEO local, casos publicados | G153: 150 | I153: 700
A158: =IF('EL QUÉ'!A13="","",'EL QUÉ'!A13) | C158: Vertical bodegas y e-commerce: visita comercial y demo sectorial | G158: 50 | I158: 400
A163: =IF('EL QUÉ'!A18="","",'EL QUÉ'!A18) | C163: Alianza con imprentas y rotulación; portfolio visual en Instagram | G163: 50 | I163: 300
A168: =IF('EL QUÉ'!A23="","",'EL QUÉ'!A23) | C168: Venta cruzada en la entrega de cada proyecto; revisión trimestral | G168: 25 | I168: 100
A173: =IF('EL QUÉ'!A28="","",'EL QUÉ'!A28) | C173: Diagnóstico digital gratuito de 15 minutos como puerta de entrada | G173: 25 | I173: 100
B178: TOTAL | G178: =G153+G158+G163+G168+G173 | I178: =I153+I158+I163+I168+I173
A182: ¿CÓMO? | K182: Plan de Operaciones
F183: Descripción del Proceso Productivo y de los Recursos necesarios
A185: PROCESO PRODUCTIVO 1. Captación y primer contacto: prospección directa del Socio 2, prescriptor o formulario. 2. Diagnóstico digital gratuito de 15 minutos: estado de la web, ficha de Google, velocidad, seguridad y posicionamiento local. Lo ejecuta el Socio 2 en la propia visita, con guion estandarizado. 3. Propuesta cerrada con alcance, plazo y precio. Siempre con opción de cuota de mantenimiento incluida. 4. Contrato y anticipo del 50%. No se empieza sin anticipo. 5. Briefing de contenidos y recopilación de material del cliente (fase que más retrasos causa: se fija plazo máximo de 15 días). 6. Diseño y desarrollo por la Socia 1, con subcontratación a freelances en los picos. Uso de IA generativa para borradores de texto e imagen, siempre con revisión humana y validación del cliente. 7. Revisión con el cliente y dos rondas de cambios incluidas. La tercera se factura. 8. Testeo (móvil, velocidad, formularios, RGPD y cookies) y publicación. 9. Cobro del 50% restante ANTES de entregar accesos. 10. Formación básica al cliente y alta en el plan de mantenimiento. 11. Mantenimiento mensual: copias, actualizaciones, seguridad, soporte y revisión trimestral presencial, que aprovecha el Socio 2 para detectar nueva venta. RECURSOS NECESARIOS Portátil de producción, monitor secundario, smartphone e impresora/escáner. WordPress como gestor de contenidos estándar; hosting gestionado externo. Adobe Creative Cloud y Figma para diseño. Herramientas de SEO local y de IA generativa. Dos puestos en coworking en Ponferrada y conectividad de fibra. Red de freelances de confianza para absorber picos sin crear estructura fija. Biblioteca propia de plantillas, checklists y procesos documentados: es lo que impide que el margen dependa de rehacer el trabajo en cada cliente. CAPACIDAD Y CUELLO DE BOTELLA: 29 proyectos al año (14 web esencial, 4 web profesional, 11 identidad gráfica), unos 2,4 al mes, más la cartera recurrente. Toda la producción recae en la Socia 1, así que la capacidad de ENTREGA, no la de venta, es el límite del Año 1. Por eso el coste de ventas incluye subcontratación variable y por eso la primera contratación por cuenta ajena se planifica para el Año 2.
...

Sheet EL QUÉ
A1: ¿EL QUÉ?
F4: Productos/Servicios que materializan la Idea
A6: Nombre | E6: Descripción | I6: Posicionamiento en Precio en el Sector
A8: Web esencial | C8: Sitio corporativo de hasta 6 secciones sobre WordPress: diseño a medida, responsive, textos base, ficha de Google Business, aviso legal y cookies. Plazo 2-3 semanas. Incluye 2 rondas de cambios. | I8: Medio
A13: Web profesional / e-commerce | C13: Tienda online o sitio avanzado: catalogo, pasarela de pago, multiidioma, integraciones (reservas, facturación, envios). Plazo 6-8 semanas. Producto estrella del vertical de bodegas DO Bierzo. | I13: Medio-Alto
A18: Identidad visual y diseño gráfico | C18: Logotipo, manual básico de marca y aplicaciones (papelería, cartelería, RRSS, rotulación). Plazo 2-4 semanas. Se vende como paquete con la web. | I18: Medio
A23: Mantenimiento web gestionado (cuota) | C23: RECURRENTE, 60 EUR/mes. Copias de seguridad, actualizaciones, seguridad, monitorización, pequeños cambios de contenido y revisión trimestral presencial. Permanencia mínima 12 meses. | I23: Medio
A28: SEO local y Google Business (cuota) | C28: RECURRENTE, 250 EUR/mes. Posicionamiento en busquedas locales del Bierzo, gestión de la ficha de Google, contenido mensual, resenas e informe de resultados. Permanencia mínima 6 meses. | I28: Medio
E32: Alto
E33: Medio
E34: Bajo
A39: ¿EL QUÉ?
F42: Matriz Productos/Servicios - Segmentos de Clientes
D45: Segmento Clientes 1 | E45: Segmento Clientes 2 | F45: Segmento Clientes 3 | G45: Segmento Clientes 4 | H45: Segmento Clientes 5 | I45: Segmentos Alternativos
B47: =A8 | D47: SI | E47: SI | F47: SI | G47: SI | I47: SI
B50: =IF(A13="","",A13) | D50: SI | F50: SI | G50: SI
B53: =IF(A18="","",A18) | D53: SI | E53: SI | F53: SI | G53: SI | I53: SI
B56: =IF(A23="","",A23) | D56: SI | E56: SI | F56: SI | G56: SI | I56: SI
B59: =IF(A28="","",A28) | D59: SI | E59: SI | F59: SI | G59: SI
D65: SI
A75: ¿EL QUÉ?
F78: Alianzas Estratégicas
A80: ALIANZAS ESTRATÉGICAS 1. PARTNER TECNOLÓGICO DE HOSTING GESTIONADO. Acuerdo a medio plazo con cuota periódica y programa de revendedor con proveedores españoles (Webempresa, Siteground, Arsys, Ionos, Gigas, Acens). Es lo que permite ofrecer la cuota de mantenimiento con margen y sin infraestructura propia. Exigir portabilidad y sin permanencia larga: los proveedores de este sector son sustituibles y no conviene quedar atrapada. 2. GESTORÍAS Y ASESORIAS DE PONFERRADA (prescriptores). Son quienes están acompañando a los micronegocios en la transición a la factura electrónica obligatoria y tienen la confianza del decisor. Acuerdo de comisión por cliente derivado. 3. IMPRENTAS Y ROTULACIÓN DEL BIERZO. Alianza cruzada: ellos derivan el trabajo web que no cubren, este negocio les deriva toda la producción impresa. Coste de captación cero para ambos. 4. AGENCIAS DE MARKETING DE LEÓN Y PONFERRADA. Subcontratación de producción web y gráfica cuando les desborda la carga. Margen menor pero flujo estable y sin coste comercial. 5. CONSEJO REGULADOR DE LA DO BIERZO, CÁMARA DE COMERCIO DE LEÓN Y CONFEBIERZO. Acceso al vertical de bodegas y credibilidad institucional en la comarca. 6. CENTRO DE INNOVACIÓN Y EMPRENDIMIENTO DE PONFERRADA. Red de contactos, visibilidad y acceso a programas de apoyo municipales. 7. FREELANCES DE PRODUCCIÓN (desarrollo, redacción, fotografía). Red de colaboradores para absorber picos sin crear estructura fija. Es la valvula que permite aceptar un proyecto grande sin contratar.
A111: ¿EL QUÉ?
F114: RESUMEN
C122: Web, diseño gráfico y servicios recurrentes

Sheet CUÁNTO Y CUÁNDO
A1: ¿CUÁNTO Y CUÁNDO? | P1: Plan Financiero
I5: Hipótesis
B9: TIPOS DE IMPUESTO QUE SE APLICARÁN AL NEGOCIO
F11: Impuesto de las Compras | G11: 0.21
F13: Impuesto de las Ventas | G13: 0.21
G14: =IF(G11="R.E.","(En Recargo de Equivalencia elegir 0%)","")
F15: Impuesto de los Gastos Generales | G15: 0.21
B18: IMPUESTO SOBRE BENEFICIOS POR EL QUE TRIBUTARÁ EL NEGOCIO
C20: Tipo impositivo | D20: ='CÓMO'!F401 | F20: =IF(D20=25%,P28,IF(D20=20%,P29,IF(D20=15%,P31,P30)))
F21: =IF(D20=25%," Tipo del 15% los dos primeros años",IF(D20=20%," Bonificación del 20% del Rendimiento Neto los dos primeros años",IF(D20=15%," Retención del 7% los dos primeros años"," Módulo Trimestral:")))
B25: INFLACIÓN ANUAL MEDIA ESPERADA: | H25: 0.03
A26: 100 | B26: 200 | C26: 300 | D26: 400 | E26: 500 | F26: 600 | G26: 700 | H26: 800 | I26: 900 | J26: 1000 | K26: 1200 | L26: 1400 | M26: 1600 | N26: 1800 | O26: 2000 | P26: 2500
A27: =M117 | B27: =O117
A28: 0.07 | B28: 0.07 | G28: 0.25 | P28: Impuesto sobre Sociedades
A29: 0.03 | B29: 0.03 | G29: 0.2 | P29: IRPF en Estimación Directa
A30: 0.0275 | B30: 0.15 | G30: MÓDULOS | P30: IRPF en Estimación Objetiva
A31: 0 | B31: 0 | G31: 0.15 | P31: Retención de IRPF en Facturas
B32: R.E.
A39: ¿CUÁNTO Y CUÁNDO? | P39: Plan Financiero
A41: INVERSIÓN INICIAL | J41: FUENTES DE FINANCIACIÓN INICIALES
D42: TODOS LOS DATOS SON | E42: =IF($G$13=0%,"CON IVA","SIN IVA") | N42: Importe | P42: %
D43: Importe | F43: % | G43: % Amort. | J43: Aportaciones Dinerarias | N43: 10000 | P43: =IF($N$50=0,"",N43/$N$50)
A44: Terrenos | F44: =IF($D$69<>0,D44/$D$69,"") | G44: 0 | J44: Aportaciones no Dinerarias | P44: =IF($N$50=0,"",N44/$N$50)
A45: Edificios y Construcciones | F45: =IF($D$69<>0,D45/$D$69,"") | G45: 0.02 | J45: Subvenciones | P45: =IF($N$50=0,"",N45/$N$50)
A46: Instalaciones | F46: =IF($D$69<>0,D46/$D$69,"") | G46: 0.1 | J46: RECURSOS PROPIOS | N46: =N43+N44+N45 | P46: =IF($N$50=0,"",N46/$N$50)
A47: Maquinaria | F47: =IF($D$69<>0,D47/$D$69,"") | G47: 0.12 | J47: Préstamos a Largo Plazo | P47: =IF($N$50=0,"",N47/$N$50)
A48: Herramientas | F48: =IF($D$69<>0,D48/$D$69,"") | G48: 0.3 | J48: Otros Acreed. o Proveed. a Largo Plazo | P48: =IF($N$50=0,"",N48/$N$50)
A49: Mobiliario | D49: 400 | F49: =IF($D$69<>0,D49/$D$69,"") | G49: 0.1 | J49: RECURSOS AJENOS | N49: =N47+N48 | P49: =IF($N$50=0,"",N49/$N$50)
A50: Elementos de Transporte | F50: =IF($D$69<>0,D50/$D$69,"") | G50: 0.16 | J50: TOTAL FUENTES DE FINANCIACIÓN | N50: =N46+N49 | P50: =IF($N$55=0,"",N50/$N$51)
A51: Equipos Informáticos | D51: =IF(G13=0%,'CÓMO'!F254*1.21,'CÓMO'!F254) | F51: =IF($D$69<>0,D51/$D$69,"") | G51: 0.25
A52: Otro Inmovilizado Material | D52: 400 | F52: =IF($D$69<>0,D52/$D$69,"") | G52: 0.1 | I52: AÑO 2 | N52: AÑO 3
A53: Activos No Corrientes Mater. | D53: =SUM(D44:D52) | F53: =IF($D$69<>0,D53/$D$69,"") | I53: Inversiones
A54: Aplicaciones Informáticas | D54: =IF(G13=0%,('CÓMO'!F259+'CÓMO'!F264)*1.21,'CÓMO'!F259+'CÓMO'!F264) | F54: =IF($D$69<>0,D54/$D$69,"") | G54: 0.25 | I54: % Amortización
A55: Patentes | F55: =IF($D$69<>0,D55/$D$69,"") | G55: 0.25 | I55: Financiación Propia | L55: =IF(L53<L56,0,L53-L56-L57)
A56: Otro Inmovilizado Inmaterial | F56: =IF($D$69<>0,D56/$D$69,"") | G56: 0.25 | I56: Subvenciones | P56: =IF(L57<0,"ERROR","")
A57: Activos No Corrientes Inmater. | D57: =SUM(D54:D56) | F57: =IF($D$69<>0,D57/$D$69,"") | I57: Financiación Ajena
A58: Fianza Local | F58: =IF($D$69<>0,D58/$D$69,"") | G58: 0 | I58: Tipo de Financiación
A59: Activos No Corr. Financieros | D59: =D58 | F59: =IF($D$69<>0,D59/$D$69,"") | I59: Plazo (meses)
A60: TOTAL ACTIVOS NO CORRIENTES | D60: =D53+D57+D59 | F60: =IF($D$69<>0,D60/$D$69,"") | G60: =IF(D60<>0,(D44*G44+D45*G45+D46*G46+D47*G47+D48*G48+D49*G49+D50*G50+D51*G51+D52*G52+D54*G54+D55*G55+D56*G56+D58*G58)/D60,0) | I60: Cuota | L60: =IF(L59=0,0,PMT($L$58/12,$L$59,-$L$57,0)) | N60: =L60
A61: Gastos de Constitución | D61: 600 | F61: =IF($D$69<>0,D61/$D$69,"") | I61: Gastos Financieros | L61: =L60*12-(L57-L62) | N61: =N60*12-(L62-N62)
...
